message
🧪 Функциональные тесты
------------------------------
❌ Некоторые функциональные тесты не пройдены:
""
============================= test session starts =============================
"platform win32 -- Python 3.13.5, pytest-8.4.1, pluggy-1.6.0"
rootdir: C:\Users\mira1\OneDrive\Документы\Политех\3 курс\6 семестр\Практика\recom_sys_checker
collected 11 items
""
logic\tests\collaborative_tests.py ........ssF
""
================================== FAILURES ===================================
__________________________ test_evaluate_recall_at_3 __________________________
""
"task_info = {'algorithm': 'k-NN', 'dataset': 'movie_ratings.csv', 'filter_type': 'item_based', 'k': 10, ...}"
""
    def test_evaluate_recall_at_3(task_info):
"        if task_info[""metric""] != ""recall@3"":"
"            pytest.skip(""Метрика в задании не RMSE"")"
    
        train = get_dummy_data(seed=99)
        solution = load_solution_module()
        solution.fit(train)
    
"        user_id = train[""user_id""].iloc[0]"
        k = 3
"        # Два релевантных item’а, из них один рекомендован — ожидаем recall 0.5"
        test = pd.DataFrame([
"            {""user_id"": user_id, ""item"": 115, ""rating"": 4},"
"            {""user_id"": user_id, ""item"": 116, ""rating"": 5},"
"            {""user_id"": user_id, ""item"": 117, ""rating"": 2},  # не релевантный"
        ])
    
"        recs = solution.recommend(user_id, k=k)"
    
"        relevant = {115, 116}"
        retrieved_relevant = len(set(recs) & relevant)
        expected_recall = retrieved_relevant / len(relevant)
    
        result = solution.evaluate(test)
    
"        assert isinstance(result, float)"
>       assert abs(result - expected_recall) < 0.01
E       assert 1.0096861277165448 < 0.01
E        +  where 1.0096861277165448 = abs((1.5096861277165448 - 0.5))
""
logic\tests\collaborative_tests.py:206: AssertionError
=========================== short test summary info ===========================
FAILED logic/tests/collaborative_tests.py::test_evaluate_recall_at_3 - assert...
"=================== 1 failed, 8 passed, 2 skipped in 1.38s ===================="
""
""
""
""
🎨 Стиль кода (flake8)
------------------------------
❌ flake8: Найдены проблемы со стилем:
solution.py:0:1: E902 FileNotFoundError: [Errno 2] No such file or directory: 'solution.py'
""
""
🧱 Форматирование кода (black)
------------------------------
❌ black: Форматирование отличается от стандарта black.
""
📋 Подробности:
